[2025-09-27T07:14:49.623+0000] {taskinstance.py:1956} INFO - Dependencies all met for dep_context=non-requeueable deps ti=<TaskInstance: daily_optimization_suggestions.run_clustering manual__2025-09-27T06:26:08.885187+00:00 [queued]>
[2025-09-27T07:14:49.642+0000] {taskinstance.py:1956} INFO - Dependencies all met for dep_context=requeueable deps ti=<TaskInstance: daily_optimization_suggestions.run_clustering manual__2025-09-27T06:26:08.885187+00:00 [queued]>
[2025-09-27T07:14:49.643+0000] {taskinstance.py:2170} INFO - Starting attempt 3 of 3
[2025-09-27T07:14:49.679+0000] {taskinstance.py:2191} INFO - Executing <Task(PythonOperator): run_clustering> on 2025-09-27 06:26:08.885187+00:00
[2025-09-27T07:14:49.707+0000] {standard_task_runner.py:60} INFO - Started process 1896 to run task
[2025-09-27T07:14:49.741+0000] {standard_task_runner.py:87} INFO - Running: ['airflow', 'tasks', 'run', 'daily_optimization_suggestions', 'run_clustering', 'manual__2025-09-27T06:26:08.885187+00:00', '--job-id', '7', '--raw', '--subdir', 'DAGS_FOLDER/optimization_dag.py', '--cfg-path', '/tmp/tmp_i89kmy3']
[2025-09-27T07:14:49.746+0000] {standard_task_runner.py:88} INFO - Job 7: Subtask run_clustering
[2025-09-27T07:14:50.251+0000] {task_command.py:423} INFO - Running <TaskInstance: daily_optimization_suggestions.run_clustering manual__2025-09-27T06:26:08.885187+00:00 [running]> on host 6c490fe88578
[2025-09-27T07:14:50.429+0000] {taskinstance.py:2480} INFO - Exporting env vars: AIRFLOW_CTX_DAG_OWNER='airflow' AIRFLOW_CTX_DAG_ID='daily_optimization_suggestions' AIRFLOW_CTX_TASK_ID='run_clustering' AIRFLOW_CTX_EXECUTION_DATE='2025-09-27T06:26:08.885187+00:00' AIRFLOW_CTX_TRY_NUMBER='3' AIRFLOW_CTX_DAG_RUN_ID='manual__2025-09-27T06:26:08.885187+00:00'
[2025-09-27T07:14:50.469+0000] {taskinstance.py:2698} ERROR - Task failed with exception
Traceback (most recent call last):
  File "/home/airflow/.local/lib/python3.8/site-packages/airflow/models/taskinstance.py", line 433, in _execute_task
    result = execute_callable(context=context, **execute_callable_kwargs)
  File "/home/airflow/.local/lib/python3.8/site-packages/airflow/operators/python.py", line 199, in execute
    return_value = self.execute_callable()
  File "/home/airflow/.local/lib/python3.8/site-packages/airflow/operators/python.py", line 216, in execute_callable
    return self.python_callable(*self.op_args, **self.op_kwargs)
  File "/opt/airflow/dags/optimization_dag.py", line 38, in run_clustering
    df = pd.read_csv('/tmp/current_data.csv')
  File "/home/airflow/.local/lib/python3.8/site-packages/pandas/io/parsers/readers.py", line 912, in read_csv
    return _read(filepath_or_buffer, kwds)
  File "/home/airflow/.local/lib/python3.8/site-packages/pandas/io/parsers/readers.py", line 577, in _read
    parser = TextFileReader(filepath_or_buffer, **kwds)
  File "/home/airflow/.local/lib/python3.8/site-packages/pandas/io/parsers/readers.py", line 1407, in __init__
    self._engine = self._make_engine(f, self.engine)
  File "/home/airflow/.local/lib/python3.8/site-packages/pandas/io/parsers/readers.py", line 1679, in _make_engine
    return mapping[engine](f, **self.options)
  File "/home/airflow/.local/lib/python3.8/site-packages/pandas/io/parsers/c_parser_wrapper.py", line 93, in __init__
    self._reader = parsers.TextReader(src, **kwds)
  File "pandas/_libs/parsers.pyx", line 557, in pandas._libs.parsers.TextReader.__cinit__
pandas.errors.EmptyDataError: No columns to parse from file
[2025-09-27T07:14:50.493+0000] {taskinstance.py:1138} INFO - Marking task as FAILED. dag_id=daily_optimization_suggestions, task_id=run_clustering, execution_date=20250927T062608, start_date=20250927T071449, end_date=20250927T071450
[2025-09-27T07:14:50.513+0000] {standard_task_runner.py:107} ERROR - Failed to execute job 7 for task run_clustering (No columns to parse from file; 1896)
[2025-09-27T07:14:50.537+0000] {local_task_job_runner.py:234} INFO - Task exited with return code 1
[2025-09-27T07:14:50.555+0000] {taskinstance.py:3280} INFO - 0 downstream tasks scheduled from follow-on schedule check
